[2025-07-24T15:29:05.620+0000] {local_task_job_runner.py:120} INFO - ::group::Pre task execution logs
[2025-07-24T15:29:05.681+0000] {taskinstance.py:2076} INFO - Dependencies all met for dep_context=non-requeueable deps ti=<TaskInstance: tunestream_etl_pipeline.Stage_events scheduled__2025-07-24T13:00:00+00:00 [queued]>
[2025-07-24T15:29:05.706+0000] {taskinstance.py:2076} INFO - Dependencies all met for dep_context=requeueable deps ti=<TaskInstance: tunestream_etl_pipeline.Stage_events scheduled__2025-07-24T13:00:00+00:00 [queued]>
[2025-07-24T15:29:05.707+0000] {taskinstance.py:2306} INFO - Starting attempt 2 of 4
[2025-07-24T15:29:05.733+0000] {taskinstance.py:2330} INFO - Executing <Task(PythonOperator): Stage_events> on 2025-07-24 13:00:00+00:00
[2025-07-24T15:29:05.752+0000] {standard_task_runner.py:63} INFO - Started process 349 to run task
[2025-07-24T15:29:05.759+0000] {standard_task_runner.py:90} INFO - Running: ['***', 'tasks', 'run', 'tunestream_etl_pipeline', 'Stage_events', 'scheduled__2025-07-24T13:00:00+00:00', '--job-id', '65', '--raw', '--subdir', 'DAGS_FOLDER/final_exam_src.py', '--cfg-path', '/tmp/tmpwkyohczi']
[2025-07-24T15:29:05.766+0000] {standard_task_runner.py:91} INFO - Job 65: Subtask Stage_events
[2025-07-24T15:29:05.907+0000] {task_command.py:426} INFO - Running <TaskInstance: tunestream_etl_pipeline.Stage_events scheduled__2025-07-24T13:00:00+00:00 [running]> on host 12caace40239
[2025-07-24T15:29:06.140+0000] {taskinstance.py:2648} INFO - Exporting env vars: AIRFLOW_CTX_DAG_OWNER='***' AIRFLOW_CTX_DAG_ID='tunestream_etl_pipeline' AIRFLOW_CTX_TASK_ID='Stage_events' AIRFLOW_CTX_EXECUTION_DATE='2025-07-24T13:00:00+00:00' AIRFLOW_CTX_TRY_NUMBER='2' AIRFLOW_CTX_DAG_RUN_ID='scheduled__2025-07-24T13:00:00+00:00'
[2025-07-24T15:29:06.150+0000] {taskinstance.py:430} INFO - ::endgroup::
[2025-07-24T15:29:06.189+0000] {taskinstance.py:441} INFO - ::group::Post task execution logs
[2025-07-24T15:29:06.215+0000] {taskinstance.py:2905} ERROR - Task failed with exception
Traceback (most recent call last):
  File "/home/airflow/.local/lib/python3.10/site-packages/airflow/models/taskinstance.py", line 465, in _execute_task
    result = _execute_callable(context=context, **execute_callable_kwargs)
  File "/home/airflow/.local/lib/python3.10/site-packages/airflow/models/taskinstance.py", line 432, in _execute_callable
    return execute_callable(context=context, **execute_callable_kwargs)
  File "/home/airflow/.local/lib/python3.10/site-packages/airflow/models/baseoperator.py", line 401, in wrapper
    return func(self, *args, **kwargs)
  File "/home/airflow/.local/lib/python3.10/site-packages/airflow/operators/python.py", line 235, in execute
    return_value = self.execute_callable()
  File "/home/airflow/.local/lib/python3.10/site-packages/airflow/operators/python.py", line 252, in execute_callable
    return self.python_callable(*self.op_args, **self.op_kwargs)
  File "/opt/airflow/dags/final_exam_src.py", line 105, in load_logs_into_table
    postgres_hook.run(insert_sql, parameters=(
  File "/home/airflow/.local/lib/python3.10/site-packages/airflow/providers/common/sql/hooks/sql.py", line 431, in run
    with self._create_autocommit_connection(autocommit) as conn:
  File "/usr/local/lib/python3.10/contextlib.py", line 135, in __enter__
    return next(self.gen)
  File "/home/airflow/.local/lib/python3.10/site-packages/airflow/providers/common/sql/hooks/sql.py", line 551, in _create_autocommit_connection
    with closing(self.get_conn()) as conn:
  File "/home/airflow/.local/lib/python3.10/site-packages/airflow/providers/postgres/hooks/postgres.py", line 145, in get_conn
    conn = deepcopy(self.connection or self.get_connection(conn_id))
  File "/home/airflow/.local/lib/python3.10/site-packages/airflow/hooks/base.py", line 83, in get_connection
    conn = Connection.get_connection_from_secrets(conn_id)
  File "/home/airflow/.local/lib/python3.10/site-packages/airflow/models/connection.py", line 519, in get_connection_from_secrets
    raise AirflowNotFoundException(f"The conn_id `{conn_id}` isn't defined")
airflow.exceptions.AirflowNotFoundException: The conn_id `postgres_default` isn't defined
[2025-07-24T15:29:06.237+0000] {taskinstance.py:1206} INFO - Marking task as UP_FOR_RETRY. dag_id=tunestream_etl_pipeline, task_id=Stage_events, run_id=scheduled__2025-07-24T13:00:00+00:00, execution_date=20250724T130000, start_date=20250724T152905, end_date=20250724T152906
[2025-07-24T15:29:06.270+0000] {standard_task_runner.py:110} ERROR - Failed to execute job 65 for task Stage_events (The conn_id `postgres_default` isn't defined; 349)
[2025-07-24T15:29:06.336+0000] {local_task_job_runner.py:240} INFO - Task exited with return code 1
[2025-07-24T15:29:06.360+0000] {warnings.py:109} WARNING - /home/***/.local/lib/python3.10/site-packages/***/models/baseoperator.py:1297: AirflowProviderDeprecationWarning: Call to deprecated class PostgresOperator. (Please use `***.providers.common.sql.operators.sql.SQLExecuteQueryOperator`.Also, you can provide `hook_params={'schema': <database>}`.)
  result = cls.__new__(cls)

[2025-07-24T15:29:06.401+0000] {taskinstance.py:3503} INFO - 0 downstream tasks scheduled from follow-on schedule check
[2025-07-24T15:29:06.405+0000] {local_task_job_runner.py:222} INFO - ::endgroup::
[2025-07-24T15:40:32.388+0000] {local_task_job_runner.py:120} INFO - ::group::Pre task execution logs
[2025-07-24T15:40:32.438+0000] {taskinstance.py:2076} INFO - Dependencies all met for dep_context=non-requeueable deps ti=<TaskInstance: tunestream_etl_pipeline.Stage_events scheduled__2025-07-24T13:00:00+00:00 [queued]>
[2025-07-24T15:40:32.459+0000] {taskinstance.py:2076} INFO - Dependencies all met for dep_context=requeueable deps ti=<TaskInstance: tunestream_etl_pipeline.Stage_events scheduled__2025-07-24T13:00:00+00:00 [queued]>
[2025-07-24T15:40:32.460+0000] {taskinstance.py:2306} INFO - Starting attempt 2 of 4
[2025-07-24T15:40:32.487+0000] {taskinstance.py:2330} INFO - Executing <Task(PythonOperator): Stage_events> on 2025-07-24 13:00:00+00:00
[2025-07-24T15:40:32.507+0000] {standard_task_runner.py:63} INFO - Started process 338 to run task
[2025-07-24T15:40:32.513+0000] {standard_task_runner.py:90} INFO - Running: ['***', 'tasks', 'run', 'tunestream_etl_pipeline', 'Stage_events', 'scheduled__2025-07-24T13:00:00+00:00', '--job-id', '62', '--raw', '--subdir', 'DAGS_FOLDER/final_exam_src.py', '--cfg-path', '/tmp/tmpoqxns_tp']
[2025-07-24T15:40:32.521+0000] {standard_task_runner.py:91} INFO - Job 62: Subtask Stage_events
[2025-07-24T15:40:32.652+0000] {task_command.py:426} INFO - Running <TaskInstance: tunestream_etl_pipeline.Stage_events scheduled__2025-07-24T13:00:00+00:00 [running]> on host 562a5fa0e436
[2025-07-24T15:40:32.825+0000] {taskinstance.py:2648} INFO - Exporting env vars: AIRFLOW_CTX_DAG_OWNER='QuangBLM1' AIRFLOW_CTX_DAG_ID='tunestream_etl_pipeline' AIRFLOW_CTX_TASK_ID='Stage_events' AIRFLOW_CTX_EXECUTION_DATE='2025-07-24T13:00:00+00:00' AIRFLOW_CTX_TRY_NUMBER='2' AIRFLOW_CTX_DAG_RUN_ID='scheduled__2025-07-24T13:00:00+00:00'
[2025-07-24T15:40:32.830+0000] {taskinstance.py:430} INFO - ::endgroup::
[2025-07-24T15:40:32.871+0000] {taskinstance.py:441} INFO - ::group::Post task execution logs
[2025-07-24T15:40:32.890+0000] {taskinstance.py:2905} ERROR - Task failed with exception
Traceback (most recent call last):
  File "/home/airflow/.local/lib/python3.10/site-packages/airflow/models/taskinstance.py", line 465, in _execute_task
    result = _execute_callable(context=context, **execute_callable_kwargs)
  File "/home/airflow/.local/lib/python3.10/site-packages/airflow/models/taskinstance.py", line 432, in _execute_callable
    return execute_callable(context=context, **execute_callable_kwargs)
  File "/home/airflow/.local/lib/python3.10/site-packages/airflow/models/baseoperator.py", line 401, in wrapper
    return func(self, *args, **kwargs)
  File "/home/airflow/.local/lib/python3.10/site-packages/airflow/operators/python.py", line 235, in execute
    return_value = self.execute_callable()
  File "/home/airflow/.local/lib/python3.10/site-packages/airflow/operators/python.py", line 252, in execute_callable
    return self.python_callable(*self.op_args, **self.op_kwargs)
  File "/opt/airflow/dags/final_exam_src.py", line 105, in load_logs_into_table
    postgres_hook.run(insert_sql, parameters=(
  File "/home/airflow/.local/lib/python3.10/site-packages/airflow/providers/common/sql/hooks/sql.py", line 431, in run
    with self._create_autocommit_connection(autocommit) as conn:
  File "/usr/local/lib/python3.10/contextlib.py", line 135, in __enter__
    return next(self.gen)
  File "/home/airflow/.local/lib/python3.10/site-packages/airflow/providers/common/sql/hooks/sql.py", line 551, in _create_autocommit_connection
    with closing(self.get_conn()) as conn:
  File "/home/airflow/.local/lib/python3.10/site-packages/airflow/providers/postgres/hooks/postgres.py", line 145, in get_conn
    conn = deepcopy(self.connection or self.get_connection(conn_id))
  File "/home/airflow/.local/lib/python3.10/site-packages/airflow/hooks/base.py", line 83, in get_connection
    conn = Connection.get_connection_from_secrets(conn_id)
  File "/home/airflow/.local/lib/python3.10/site-packages/airflow/models/connection.py", line 519, in get_connection_from_secrets
    raise AirflowNotFoundException(f"The conn_id `{conn_id}` isn't defined")
airflow.exceptions.AirflowNotFoundException: The conn_id `postgres_default` isn't defined
[2025-07-24T15:40:32.912+0000] {taskinstance.py:1206} INFO - Marking task as UP_FOR_RETRY. dag_id=tunestream_etl_pipeline, task_id=Stage_events, run_id=scheduled__2025-07-24T13:00:00+00:00, execution_date=20250724T130000, start_date=20250724T154032, end_date=20250724T154032
[2025-07-24T15:40:32.939+0000] {standard_task_runner.py:110} ERROR - Failed to execute job 62 for task Stage_events (The conn_id `postgres_default` isn't defined; 338)
[2025-07-24T15:40:33.009+0000] {local_task_job_runner.py:240} INFO - Task exited with return code 1
[2025-07-24T15:40:33.030+0000] {local_task_job_runner.py:222} INFO - ::endgroup::
