[2025-07-24T16:20:59.036+0000] {local_task_job_runner.py:120} INFO - ::group::Pre task execution logs
[2025-07-24T16:20:59.067+0000] {taskinstance.py:2076} INFO - Dependencies all met for dep_context=non-requeueable deps ti=<TaskInstance: tunestream_etl_pipeline.Stage_events manual__2025-07-24T16:20:55.060184+00:00 [queued]>
[2025-07-24T16:20:59.079+0000] {taskinstance.py:2076} INFO - Dependencies all met for dep_context=requeueable deps ti=<TaskInstance: tunestream_etl_pipeline.Stage_events manual__2025-07-24T16:20:55.060184+00:00 [queued]>
[2025-07-24T16:20:59.079+0000] {taskinstance.py:2306} INFO - Starting attempt 1 of 2
[2025-07-24T16:20:59.094+0000] {taskinstance.py:2330} INFO - Executing <Task(PythonOperator): Stage_events> on 2025-07-24 16:20:55.060184+00:00
[2025-07-24T16:20:59.104+0000] {standard_task_runner.py:63} INFO - Started process 181 to run task
[2025-07-24T16:20:59.111+0000] {standard_task_runner.py:90} INFO - Running: ['***', 'tasks', 'run', 'tunestream_etl_pipeline', 'Stage_events', 'manual__2025-07-24T16:20:55.060184+00:00', '--job-id', '3', '--raw', '--subdir', 'DAGS_FOLDER/final_exam_src.py', '--cfg-path', '/tmp/tmpzjrlvqn1']
[2025-07-24T16:20:59.116+0000] {standard_task_runner.py:91} INFO - Job 3: Subtask Stage_events
[2025-07-24T16:20:59.212+0000] {task_command.py:426} INFO - Running <TaskInstance: tunestream_etl_pipeline.Stage_events manual__2025-07-24T16:20:55.060184+00:00 [running]> on host a0f12fcdcc8f
[2025-07-24T16:20:59.320+0000] {taskinstance.py:2648} INFO - Exporting env vars: AIRFLOW_CTX_DAG_OWNER='QuangBLM1' AIRFLOW_CTX_DAG_ID='tunestream_etl_pipeline' AIRFLOW_CTX_TASK_ID='Stage_events' AIRFLOW_CTX_EXECUTION_DATE='2025-07-24T16:20:55.060184+00:00' AIRFLOW_CTX_TRY_NUMBER='1' AIRFLOW_CTX_DAG_RUN_ID='manual__2025-07-24T16:20:55.060184+00:00'
[2025-07-24T16:20:59.325+0000] {taskinstance.py:430} INFO - ::endgroup::
[2025-07-24T16:20:59.351+0000] {taskinstance.py:441} INFO - ::group::Post task execution logs
[2025-07-24T16:20:59.364+0000] {taskinstance.py:2905} ERROR - Task failed with exception
Traceback (most recent call last):
  File "/home/airflow/.local/lib/python3.10/site-packages/airflow/models/taskinstance.py", line 465, in _execute_task
    result = _execute_callable(context=context, **execute_callable_kwargs)
  File "/home/airflow/.local/lib/python3.10/site-packages/airflow/models/taskinstance.py", line 432, in _execute_callable
    return execute_callable(context=context, **execute_callable_kwargs)
  File "/home/airflow/.local/lib/python3.10/site-packages/airflow/models/baseoperator.py", line 401, in wrapper
    return func(self, *args, **kwargs)
  File "/home/airflow/.local/lib/python3.10/site-packages/airflow/operators/python.py", line 235, in execute
    return_value = self.execute_callable()
  File "/home/airflow/.local/lib/python3.10/site-packages/airflow/operators/python.py", line 252, in execute_callable
    return self.python_callable(*self.op_args, **self.op_kwargs)
  File "/opt/airflow/dags/final_exam_src.py", line 105, in load_logs_into_table
    postgres_hook.run(insert_sql, parameters=(
  File "/home/airflow/.local/lib/python3.10/site-packages/airflow/providers/common/sql/hooks/sql.py", line 431, in run
    with self._create_autocommit_connection(autocommit) as conn:
  File "/usr/local/lib/python3.10/contextlib.py", line 135, in __enter__
    return next(self.gen)
  File "/home/airflow/.local/lib/python3.10/site-packages/airflow/providers/common/sql/hooks/sql.py", line 551, in _create_autocommit_connection
    with closing(self.get_conn()) as conn:
  File "/home/airflow/.local/lib/python3.10/site-packages/airflow/providers/postgres/hooks/postgres.py", line 145, in get_conn
    conn = deepcopy(self.connection or self.get_connection(conn_id))
  File "/home/airflow/.local/lib/python3.10/site-packages/airflow/hooks/base.py", line 83, in get_connection
    conn = Connection.get_connection_from_secrets(conn_id)
  File "/home/airflow/.local/lib/python3.10/site-packages/airflow/models/connection.py", line 519, in get_connection_from_secrets
    raise AirflowNotFoundException(f"The conn_id `{conn_id}` isn't defined")
airflow.exceptions.AirflowNotFoundException: The conn_id `postgres_default` isn't defined
[2025-07-24T16:20:59.383+0000] {taskinstance.py:1206} INFO - Marking task as UP_FOR_RETRY. dag_id=tunestream_etl_pipeline, task_id=Stage_events, run_id=manual__2025-07-24T16:20:55.060184+00:00, execution_date=20250724T162055, start_date=20250724T162059, end_date=20250724T162059
[2025-07-24T16:20:59.401+0000] {standard_task_runner.py:110} ERROR - Failed to execute job 3 for task Stage_events (The conn_id `postgres_default` isn't defined; 181)
[2025-07-24T16:20:59.442+0000] {local_task_job_runner.py:240} INFO - Task exited with return code 1
[2025-07-24T16:20:59.457+0000] {local_task_job_runner.py:222} INFO - ::endgroup::
