[2025-07-24T15:23:10.503+0000] {local_task_job_runner.py:120} INFO - ::group::Pre task execution logs
[2025-07-24T15:23:10.663+0000] {taskinstance.py:2076} INFO - Dependencies all met for dep_context=non-requeueable deps ti=<TaskInstance: tunestream_etl_pipeline.Stage_events scheduled__2025-07-24T01:00:00+00:00 [queued]>
[2025-07-24T15:23:10.698+0000] {taskinstance.py:2076} INFO - Dependencies all met for dep_context=requeueable deps ti=<TaskInstance: tunestream_etl_pipeline.Stage_events scheduled__2025-07-24T01:00:00+00:00 [queued]>
[2025-07-24T15:23:10.700+0000] {taskinstance.py:2306} INFO - Starting attempt 1 of 4
[2025-07-24T15:23:10.961+0000] {taskinstance.py:2330} INFO - Executing <Task(PythonOperator): Stage_events> on 2025-07-24 01:00:00+00:00
[2025-07-24T15:23:10.999+0000] {standard_task_runner.py:63} INFO - Started process 121 to run task
[2025-07-24T15:23:11.084+0000] {standard_task_runner.py:90} INFO - Running: ['***', 'tasks', 'run', 'tunestream_etl_pipeline', 'Stage_events', 'scheduled__2025-07-24T01:00:00+00:00', '--job-id', '9', '--raw', '--subdir', 'DAGS_FOLDER/final_exam_src.py', '--cfg-path', '/tmp/tmp_5u4awk1']
[2025-07-24T15:23:11.133+0000] {standard_task_runner.py:91} INFO - Job 9: Subtask Stage_events
[2025-07-24T15:23:11.485+0000] {task_command.py:426} INFO - Running <TaskInstance: tunestream_etl_pipeline.Stage_events scheduled__2025-07-24T01:00:00+00:00 [running]> on host 12caace40239
[2025-07-24T15:23:12.221+0000] {taskinstance.py:2648} INFO - Exporting env vars: AIRFLOW_CTX_DAG_OWNER='***' AIRFLOW_CTX_DAG_ID='tunestream_etl_pipeline' AIRFLOW_CTX_TASK_ID='Stage_events' AIRFLOW_CTX_EXECUTION_DATE='2025-07-24T01:00:00+00:00' AIRFLOW_CTX_TRY_NUMBER='1' AIRFLOW_CTX_DAG_RUN_ID='scheduled__2025-07-24T01:00:00+00:00'
[2025-07-24T15:23:12.294+0000] {taskinstance.py:430} INFO - ::endgroup::
[2025-07-24T15:23:12.516+0000] {taskinstance.py:441} INFO - ::group::Post task execution logs
[2025-07-24T15:23:12.629+0000] {taskinstance.py:2905} ERROR - Task failed with exception
Traceback (most recent call last):
  File "/home/airflow/.local/lib/python3.10/site-packages/airflow/models/taskinstance.py", line 465, in _execute_task
    result = _execute_callable(context=context, **execute_callable_kwargs)
  File "/home/airflow/.local/lib/python3.10/site-packages/airflow/models/taskinstance.py", line 432, in _execute_callable
    return execute_callable(context=context, **execute_callable_kwargs)
  File "/home/airflow/.local/lib/python3.10/site-packages/airflow/models/baseoperator.py", line 401, in wrapper
    return func(self, *args, **kwargs)
  File "/home/airflow/.local/lib/python3.10/site-packages/airflow/operators/python.py", line 235, in execute
    return_value = self.execute_callable()
  File "/home/airflow/.local/lib/python3.10/site-packages/airflow/operators/python.py", line 252, in execute_callable
    return self.python_callable(*self.op_args, **self.op_kwargs)
  File "/opt/airflow/dags/final_exam_src.py", line 109, in load_logs_into_table
    postgres_hook.run(insert_sql, parameters=(
  File "/home/airflow/.local/lib/python3.10/site-packages/airflow/providers/common/sql/hooks/sql.py", line 431, in run
    with self._create_autocommit_connection(autocommit) as conn:
  File "/usr/local/lib/python3.10/contextlib.py", line 135, in __enter__
    return next(self.gen)
  File "/home/airflow/.local/lib/python3.10/site-packages/airflow/providers/common/sql/hooks/sql.py", line 551, in _create_autocommit_connection
    with closing(self.get_conn()) as conn:
  File "/home/airflow/.local/lib/python3.10/site-packages/airflow/providers/postgres/hooks/postgres.py", line 145, in get_conn
    conn = deepcopy(self.connection or self.get_connection(conn_id))
  File "/home/airflow/.local/lib/python3.10/site-packages/airflow/hooks/base.py", line 83, in get_connection
    conn = Connection.get_connection_from_secrets(conn_id)
  File "/home/airflow/.local/lib/python3.10/site-packages/airflow/models/connection.py", line 519, in get_connection_from_secrets
    raise AirflowNotFoundException(f"The conn_id `{conn_id}` isn't defined")
airflow.exceptions.AirflowNotFoundException: The conn_id `postgres_default` isn't defined
[2025-07-24T15:23:12.718+0000] {taskinstance.py:1206} INFO - Marking task as UP_FOR_RETRY. dag_id=tunestream_etl_pipeline, task_id=Stage_events, run_id=scheduled__2025-07-24T01:00:00+00:00, execution_date=20250724T010000, start_date=20250724T152310, end_date=20250724T152312
[2025-07-24T15:23:12.854+0000] {standard_task_runner.py:110} ERROR - Failed to execute job 9 for task Stage_events (The conn_id `postgres_default` isn't defined; 121)
[2025-07-24T15:23:12.993+0000] {local_task_job_runner.py:240} INFO - Task exited with return code 1
[2025-07-24T15:23:13.087+0000] {local_task_job_runner.py:222} INFO - ::endgroup::
[2025-07-24T15:35:11.840+0000] {local_task_job_runner.py:120} INFO - ::group::Pre task execution logs
[2025-07-24T15:35:12.001+0000] {taskinstance.py:2076} INFO - Dependencies all met for dep_context=non-requeueable deps ti=<TaskInstance: tunestream_etl_pipeline.Stage_events scheduled__2025-07-24T01:00:00+00:00 [queued]>
[2025-07-24T15:35:12.079+0000] {taskinstance.py:2076} INFO - Dependencies all met for dep_context=requeueable deps ti=<TaskInstance: tunestream_etl_pipeline.Stage_events scheduled__2025-07-24T01:00:00+00:00 [queued]>
[2025-07-24T15:35:12.082+0000] {taskinstance.py:2306} INFO - Starting attempt 1 of 4
[2025-07-24T15:35:12.203+0000] {taskinstance.py:2330} INFO - Executing <Task(PythonOperator): Stage_events> on 2025-07-24 01:00:00+00:00
[2025-07-24T15:35:12.473+0000] {standard_task_runner.py:63} INFO - Started process 109 to run task
[2025-07-24T15:35:12.479+0000] {standard_task_runner.py:90} INFO - Running: ['***', 'tasks', 'run', 'tunestream_etl_pipeline', 'Stage_events', 'scheduled__2025-07-24T01:00:00+00:00', '--job-id', '4', '--raw', '--subdir', 'DAGS_FOLDER/final_exam_src.py', '--cfg-path', '/tmp/tmpdey__iue']
[2025-07-24T15:35:12.519+0000] {standard_task_runner.py:91} INFO - Job 4: Subtask Stage_events
[2025-07-24T15:35:13.330+0000] {task_command.py:426} INFO - Running <TaskInstance: tunestream_etl_pipeline.Stage_events scheduled__2025-07-24T01:00:00+00:00 [running]> on host 562a5fa0e436
[2025-07-24T15:35:14.236+0000] {taskinstance.py:2648} INFO - Exporting env vars: AIRFLOW_CTX_DAG_OWNER='***' AIRFLOW_CTX_DAG_ID='tunestream_etl_pipeline' AIRFLOW_CTX_TASK_ID='Stage_events' AIRFLOW_CTX_EXECUTION_DATE='2025-07-24T01:00:00+00:00' AIRFLOW_CTX_TRY_NUMBER='1' AIRFLOW_CTX_DAG_RUN_ID='scheduled__2025-07-24T01:00:00+00:00'
[2025-07-24T15:35:14.254+0000] {taskinstance.py:430} INFO - ::endgroup::
[2025-07-24T15:35:14.402+0000] {taskinstance.py:441} INFO - ::group::Post task execution logs
[2025-07-24T15:35:14.457+0000] {taskinstance.py:2905} ERROR - Task failed with exception
Traceback (most recent call last):
  File "/home/airflow/.local/lib/python3.10/site-packages/airflow/models/taskinstance.py", line 465, in _execute_task
    result = _execute_callable(context=context, **execute_callable_kwargs)
  File "/home/airflow/.local/lib/python3.10/site-packages/airflow/models/taskinstance.py", line 432, in _execute_callable
    return execute_callable(context=context, **execute_callable_kwargs)
  File "/home/airflow/.local/lib/python3.10/site-packages/airflow/models/baseoperator.py", line 401, in wrapper
    return func(self, *args, **kwargs)
  File "/home/airflow/.local/lib/python3.10/site-packages/airflow/operators/python.py", line 235, in execute
    return_value = self.execute_callable()
  File "/home/airflow/.local/lib/python3.10/site-packages/airflow/operators/python.py", line 252, in execute_callable
    return self.python_callable(*self.op_args, **self.op_kwargs)
  File "/opt/airflow/dags/final_exam_src.py", line 105, in load_logs_into_table
    postgres_hook.run(insert_sql, parameters=(
  File "/home/airflow/.local/lib/python3.10/site-packages/airflow/providers/common/sql/hooks/sql.py", line 431, in run
    with self._create_autocommit_connection(autocommit) as conn:
  File "/usr/local/lib/python3.10/contextlib.py", line 135, in __enter__
    return next(self.gen)
  File "/home/airflow/.local/lib/python3.10/site-packages/airflow/providers/common/sql/hooks/sql.py", line 551, in _create_autocommit_connection
    with closing(self.get_conn()) as conn:
  File "/home/airflow/.local/lib/python3.10/site-packages/airflow/providers/postgres/hooks/postgres.py", line 145, in get_conn
    conn = deepcopy(self.connection or self.get_connection(conn_id))
  File "/home/airflow/.local/lib/python3.10/site-packages/airflow/hooks/base.py", line 83, in get_connection
    conn = Connection.get_connection_from_secrets(conn_id)
  File "/home/airflow/.local/lib/python3.10/site-packages/airflow/models/connection.py", line 519, in get_connection_from_secrets
    raise AirflowNotFoundException(f"The conn_id `{conn_id}` isn't defined")
airflow.exceptions.AirflowNotFoundException: The conn_id `postgres_default` isn't defined
[2025-07-24T15:35:14.531+0000] {taskinstance.py:1206} INFO - Marking task as UP_FOR_RETRY. dag_id=tunestream_etl_pipeline, task_id=Stage_events, run_id=scheduled__2025-07-24T01:00:00+00:00, execution_date=20250724T010000, start_date=20250724T153512, end_date=20250724T153514
[2025-07-24T15:35:14.612+0000] {standard_task_runner.py:110} ERROR - Failed to execute job 4 for task Stage_events (The conn_id `postgres_default` isn't defined; 109)
[2025-07-24T15:35:14.755+0000] {local_task_job_runner.py:240} INFO - Task exited with return code 1
[2025-07-24T15:35:14.944+0000] {warnings.py:109} WARNING - /home/***/.local/lib/python3.10/site-packages/***/models/baseoperator.py:1297: AirflowProviderDeprecationWarning: Call to deprecated class PostgresOperator. (Please use `***.providers.common.sql.operators.sql.SQLExecuteQueryOperator`.Also, you can provide `hook_params={'schema': <database>}`.)
  result = cls.__new__(cls)

[2025-07-24T15:35:15.087+0000] {taskinstance.py:3503} INFO - 0 downstream tasks scheduled from follow-on schedule check
[2025-07-24T15:35:15.119+0000] {local_task_job_runner.py:222} INFO - ::endgroup::
