[2025-07-24T15:28:52.296+0000] {local_task_job_runner.py:120} INFO - ::group::Pre task execution logs
[2025-07-24T15:28:52.439+0000] {taskinstance.py:2076} INFO - Dependencies all met for dep_context=non-requeueable deps ti=<TaskInstance: tunestream_etl_pipeline.Stage_events scheduled__2025-07-24T06:00:00+00:00 [queued]>
[2025-07-24T15:28:52.508+0000] {taskinstance.py:2076} INFO - Dependencies all met for dep_context=requeueable deps ti=<TaskInstance: tunestream_etl_pipeline.Stage_events scheduled__2025-07-24T06:00:00+00:00 [queued]>
[2025-07-24T15:28:52.510+0000] {taskinstance.py:2306} INFO - Starting attempt 2 of 4
[2025-07-24T15:28:52.581+0000] {taskinstance.py:2330} INFO - Executing <Task(PythonOperator): Stage_events> on 2025-07-24 06:00:00+00:00
[2025-07-24T15:28:52.649+0000] {standard_task_runner.py:63} INFO - Started process 293 to run task
[2025-07-24T15:28:52.682+0000] {standard_task_runner.py:90} INFO - Running: ['***', 'tasks', 'run', 'tunestream_etl_pipeline', 'Stage_events', 'scheduled__2025-07-24T06:00:00+00:00', '--job-id', '44', '--raw', '--subdir', 'DAGS_FOLDER/final_exam_src.py', '--cfg-path', '/tmp/tmpl_jvahye']
[2025-07-24T15:28:52.738+0000] {standard_task_runner.py:91} INFO - Job 44: Subtask Stage_events
[2025-07-24T15:28:53.218+0000] {task_command.py:426} INFO - Running <TaskInstance: tunestream_etl_pipeline.Stage_events scheduled__2025-07-24T06:00:00+00:00 [running]> on host 12caace40239
[2025-07-24T15:28:53.728+0000] {taskinstance.py:2648} INFO - Exporting env vars: AIRFLOW_CTX_DAG_OWNER='***' AIRFLOW_CTX_DAG_ID='tunestream_etl_pipeline' AIRFLOW_CTX_TASK_ID='Stage_events' AIRFLOW_CTX_EXECUTION_DATE='2025-07-24T06:00:00+00:00' AIRFLOW_CTX_TRY_NUMBER='2' AIRFLOW_CTX_DAG_RUN_ID='scheduled__2025-07-24T06:00:00+00:00'
[2025-07-24T15:28:53.795+0000] {taskinstance.py:430} INFO - ::endgroup::
[2025-07-24T15:28:54.055+0000] {taskinstance.py:441} INFO - ::group::Post task execution logs
[2025-07-24T15:28:54.155+0000] {taskinstance.py:2905} ERROR - Task failed with exception
Traceback (most recent call last):
  File "/home/airflow/.local/lib/python3.10/site-packages/airflow/models/taskinstance.py", line 465, in _execute_task
    result = _execute_callable(context=context, **execute_callable_kwargs)
  File "/home/airflow/.local/lib/python3.10/site-packages/airflow/models/taskinstance.py", line 432, in _execute_callable
    return execute_callable(context=context, **execute_callable_kwargs)
  File "/home/airflow/.local/lib/python3.10/site-packages/airflow/models/baseoperator.py", line 401, in wrapper
    return func(self, *args, **kwargs)
  File "/home/airflow/.local/lib/python3.10/site-packages/airflow/operators/python.py", line 235, in execute
    return_value = self.execute_callable()
  File "/home/airflow/.local/lib/python3.10/site-packages/airflow/operators/python.py", line 252, in execute_callable
    return self.python_callable(*self.op_args, **self.op_kwargs)
  File "/opt/airflow/dags/final_exam_src.py", line 105, in load_logs_into_table
    postgres_hook.run(insert_sql, parameters=(
  File "/home/airflow/.local/lib/python3.10/site-packages/airflow/providers/common/sql/hooks/sql.py", line 431, in run
    with self._create_autocommit_connection(autocommit) as conn:
  File "/usr/local/lib/python3.10/contextlib.py", line 135, in __enter__
    return next(self.gen)
  File "/home/airflow/.local/lib/python3.10/site-packages/airflow/providers/common/sql/hooks/sql.py", line 551, in _create_autocommit_connection
    with closing(self.get_conn()) as conn:
  File "/home/airflow/.local/lib/python3.10/site-packages/airflow/providers/postgres/hooks/postgres.py", line 145, in get_conn
    conn = deepcopy(self.connection or self.get_connection(conn_id))
  File "/home/airflow/.local/lib/python3.10/site-packages/airflow/hooks/base.py", line 83, in get_connection
    conn = Connection.get_connection_from_secrets(conn_id)
  File "/home/airflow/.local/lib/python3.10/site-packages/airflow/models/connection.py", line 519, in get_connection_from_secrets
    raise AirflowNotFoundException(f"The conn_id `{conn_id}` isn't defined")
airflow.exceptions.AirflowNotFoundException: The conn_id `postgres_default` isn't defined
[2025-07-24T15:28:54.287+0000] {taskinstance.py:1206} INFO - Marking task as UP_FOR_RETRY. dag_id=tunestream_etl_pipeline, task_id=Stage_events, run_id=scheduled__2025-07-24T06:00:00+00:00, execution_date=20250724T060000, start_date=20250724T152852, end_date=20250724T152854
[2025-07-24T15:28:54.496+0000] {standard_task_runner.py:110} ERROR - Failed to execute job 44 for task Stage_events (The conn_id `postgres_default` isn't defined; 293)
[2025-07-24T15:28:54.668+0000] {local_task_job_runner.py:240} INFO - Task exited with return code 1
[2025-07-24T15:28:54.866+0000] {local_task_job_runner.py:222} INFO - ::endgroup::
[2025-07-24T15:40:23.713+0000] {local_task_job_runner.py:120} INFO - ::group::Pre task execution logs
[2025-07-24T15:40:23.752+0000] {taskinstance.py:2076} INFO - Dependencies all met for dep_context=non-requeueable deps ti=<TaskInstance: tunestream_etl_pipeline.Stage_events scheduled__2025-07-24T06:00:00+00:00 [queued]>
[2025-07-24T15:40:23.767+0000] {taskinstance.py:2076} INFO - Dependencies all met for dep_context=requeueable deps ti=<TaskInstance: tunestream_etl_pipeline.Stage_events scheduled__2025-07-24T06:00:00+00:00 [queued]>
[2025-07-24T15:40:23.768+0000] {taskinstance.py:2306} INFO - Starting attempt 2 of 4
[2025-07-24T15:40:23.792+0000] {taskinstance.py:2330} INFO - Executing <Task(PythonOperator): Stage_events> on 2025-07-24 06:00:00+00:00
[2025-07-24T15:40:23.806+0000] {standard_task_runner.py:63} INFO - Started process 290 to run task
[2025-07-24T15:40:23.812+0000] {standard_task_runner.py:90} INFO - Running: ['***', 'tasks', 'run', 'tunestream_etl_pipeline', 'Stage_events', 'scheduled__2025-07-24T06:00:00+00:00', '--job-id', '49', '--raw', '--subdir', 'DAGS_FOLDER/final_exam_src.py', '--cfg-path', '/tmp/tmpa59nqua4']
[2025-07-24T15:40:23.817+0000] {standard_task_runner.py:91} INFO - Job 49: Subtask Stage_events
[2025-07-24T15:40:23.934+0000] {task_command.py:426} INFO - Running <TaskInstance: tunestream_etl_pipeline.Stage_events scheduled__2025-07-24T06:00:00+00:00 [running]> on host 562a5fa0e436
[2025-07-24T15:40:24.093+0000] {taskinstance.py:2648} INFO - Exporting env vars: AIRFLOW_CTX_DAG_OWNER='QuangBLM1' AIRFLOW_CTX_DAG_ID='tunestream_etl_pipeline' AIRFLOW_CTX_TASK_ID='Stage_events' AIRFLOW_CTX_EXECUTION_DATE='2025-07-24T06:00:00+00:00' AIRFLOW_CTX_TRY_NUMBER='2' AIRFLOW_CTX_DAG_RUN_ID='scheduled__2025-07-24T06:00:00+00:00'
[2025-07-24T15:40:24.097+0000] {taskinstance.py:430} INFO - ::endgroup::
[2025-07-24T15:40:24.135+0000] {taskinstance.py:441} INFO - ::group::Post task execution logs
[2025-07-24T15:40:24.157+0000] {taskinstance.py:2905} ERROR - Task failed with exception
Traceback (most recent call last):
  File "/home/airflow/.local/lib/python3.10/site-packages/airflow/models/taskinstance.py", line 465, in _execute_task
    result = _execute_callable(context=context, **execute_callable_kwargs)
  File "/home/airflow/.local/lib/python3.10/site-packages/airflow/models/taskinstance.py", line 432, in _execute_callable
    return execute_callable(context=context, **execute_callable_kwargs)
  File "/home/airflow/.local/lib/python3.10/site-packages/airflow/models/baseoperator.py", line 401, in wrapper
    return func(self, *args, **kwargs)
  File "/home/airflow/.local/lib/python3.10/site-packages/airflow/operators/python.py", line 235, in execute
    return_value = self.execute_callable()
  File "/home/airflow/.local/lib/python3.10/site-packages/airflow/operators/python.py", line 252, in execute_callable
    return self.python_callable(*self.op_args, **self.op_kwargs)
  File "/opt/airflow/dags/final_exam_src.py", line 105, in load_logs_into_table
    postgres_hook.run(insert_sql, parameters=(
  File "/home/airflow/.local/lib/python3.10/site-packages/airflow/providers/common/sql/hooks/sql.py", line 431, in run
    with self._create_autocommit_connection(autocommit) as conn:
  File "/usr/local/lib/python3.10/contextlib.py", line 135, in __enter__
    return next(self.gen)
  File "/home/airflow/.local/lib/python3.10/site-packages/airflow/providers/common/sql/hooks/sql.py", line 551, in _create_autocommit_connection
    with closing(self.get_conn()) as conn:
  File "/home/airflow/.local/lib/python3.10/site-packages/airflow/providers/postgres/hooks/postgres.py", line 145, in get_conn
    conn = deepcopy(self.connection or self.get_connection(conn_id))
  File "/home/airflow/.local/lib/python3.10/site-packages/airflow/hooks/base.py", line 83, in get_connection
    conn = Connection.get_connection_from_secrets(conn_id)
  File "/home/airflow/.local/lib/python3.10/site-packages/airflow/models/connection.py", line 519, in get_connection_from_secrets
    raise AirflowNotFoundException(f"The conn_id `{conn_id}` isn't defined")
airflow.exceptions.AirflowNotFoundException: The conn_id `postgres_default` isn't defined
[2025-07-24T15:40:24.175+0000] {taskinstance.py:1206} INFO - Marking task as UP_FOR_RETRY. dag_id=tunestream_etl_pipeline, task_id=Stage_events, run_id=scheduled__2025-07-24T06:00:00+00:00, execution_date=20250724T060000, start_date=20250724T154023, end_date=20250724T154024
[2025-07-24T15:40:24.200+0000] {standard_task_runner.py:110} ERROR - Failed to execute job 49 for task Stage_events (The conn_id `postgres_default` isn't defined; 290)
[2025-07-24T15:40:24.267+0000] {local_task_job_runner.py:240} INFO - Task exited with return code 1
[2025-07-24T15:40:24.288+0000] {local_task_job_runner.py:222} INFO - ::endgroup::
